<?xml version="1.0"?>
<robot name="agv_bot" xmlns:xacro="http://www.ros.org/wiki/xacro">

  <!-- Define robot constants -->
  <xacro:property name="base_width" value="0.47"/>
  <xacro:property name="base_length" value="0.60"/>
  <xacro:property name="base_height" value="0.189"/>

  <xacro:property name="wheel_radius" value="0.075"/>
  <xacro:property name="wheel_width" value="0.031"/>
  <xacro:property name="wheel_ygap" value="0.025"/>
  <xacro:property name="wheel_zoff" value="0.05"/>
  <xacro:property name="wheel_xoff" value="0.12"/>

  <xacro:property name="caster_xoff" value="0.10"/>

  <!-- <xacro:include filename="$(find agv_bot_description)/src/description/macro.urdf" />
  <xacro:include filename="$(find agv_bot_description)/src/description/materials.xacro" /> -->

  <!-- Define intertial property macros  -->
  <xacro:macro name="box_inertia" params="m w h d">
    <inertial>
      <origin xyz="0 0 0" rpy="${pi/2} 0 ${pi/2}"/>
      <mass value="${m}"/>
      <inertia ixx="${(m/12) * (h*h + d*d)}" ixy="0.0" ixz="0.0" iyy="${(m/12) * (w*w + d*d)}" iyz="0.0" izz="${(m/12) * (w*w + h*h)}"/>
    </inertial>
  </xacro:macro>

  <xacro:macro name="cylinder_inertia" params="m r h">
    <inertial>
      <origin xyz="0 0 0" rpy="${pi/2} 0 0" />
      <mass value="${m}"/>
      <inertia ixx="${(m/12) * (3*r*r + h*h)}" ixy = "0" ixz = "0" iyy="${(m/12) * (3*r*r + h*h)}" iyz = "0" izz="${(m/2) * (r*r)}"/>
    </inertial>
  </xacro:macro>

  <xacro:macro name="sphere_inertia" params="m r">
    <inertial>
      <mass value="${m}"/>
      <inertia ixx="${(2/5) * m * (r*r)}" ixy="0.0" ixz="0.0" iyy="${(2/5) * m * (r*r)}" iyz="0.0" izz="${(2/5) * m * (r*r)}"/>
    </inertial>
  </xacro:macro>


  <!-- Define Color -->
  <material name="Black">
    <color rgba="0.0 0.0 0.0 0.6"/>
  </material>
  <material name="White">
    <color rgba="1.0 1.0 1.0 1.0"/>
  </material>
  <material name="Red">
    <color rgba="1.0 0.0 0.0 1.0"/>
  </material>
  <material name="Grey">
    <color rgba="0.2 0.2 0.2 1.0"/>
  </material>  
  <material name="Orange">
    <color rgba="1.0 0.509803922 0.156862745 1.0"/>
  </material>   
  <material name="Yellow">
    <color rgba="1.0 1.0 0.0 0.4"/>
  </material>
  <material name="Cyan">
    <color rgba="0.0 1.0 1.0 1.0"/>
  </material>


  <!-- Robot Footprint -->
  <link name="base_footprint"/>

  <!-- Base_joint -->
  <joint name="base_joint" type="fixed">
    <parent link="base_link"/>
    <child link="base_footprint"/>
    <origin xyz="0.0 0.0 ${-(wheel_radius+wheel_zoff)}" rpy="0 0 0"/>
  </joint>  

  <!-- Robot Base -->
  <link name="base_link">
    <visual>
      <origin xyz="0 0 0" rpy="0 0 0"/>
      <geometry>
        <box size="${base_length} ${base_width} ${base_height}"/>
      </geometry>
      <material name="Orange"/> 
    </visual>

    <collision>
      <origin xyz="0 0 0" rpy="0 0 0"/>
      <geometry>
         <box size="${base_length} ${base_width} ${base_height}"/>
      </geometry>
    </collision>
  </link>

    <!-- Wheels -->
  <xacro:macro name="wheel" params="prefix x_reflect y_reflect">
    <link name="${prefix}_link">
      <visual>
        <origin xyz="0 0 0" rpy="${pi/2} 0 0"/>
        <geometry>
            <cylinder radius="${wheel_radius}" length="${wheel_width}"/>
        </geometry>
        <material name="Grey"/> 
      </visual>
      <collision>
        <origin xyz="0 0 0" rpy="${pi/2} 0 0"/>
        <geometry>
          <cylinder radius="${wheel_radius}" length="${wheel_width}"/>
        </geometry>
      </collision>      
    </link>

    <joint name="${prefix}_joint" type="continuous">
      <parent link="base_link"/>
      <child link="${prefix}_link"/>
      <origin xyz="0.0 ${y_reflect*(base_width/2+wheel_ygap)} ${-wheel_zoff}" rpy="0 0 0"/>
      <axis xyz="0 1 0"/>
    </joint>
  </xacro:macro>

  <xacro:wheel prefix="wheel_l" x_reflect="-1" y_reflect="1" />
  <xacro:wheel prefix="wheel_r" x_reflect="-1" y_reflect="-1" />

  <!-- Caster Wheel -->
  <!-- lf_caster -->
  <link name="lf_caster">
    <visual>
      <geometry>
        <sphere radius="${(wheel_radius+wheel_zoff-(base_height/2))}"/>
      </geometry>
      <material name="Cyan"/>
    </visual>
    <collision>
      <geometry>
        <sphere radius="${(wheel_radius+wheel_zoff-(base_height/2))}"/>
      </geometry>
    </collision>
  </link>

  <joint name="lf_caster_joint" type="fixed">
    <parent link="base_link"/>
    <child link="lf_caster"/>
    <origin xyz="0.25 0.2 ${-(base_height/2)}" rpy="0 0 0"/>
  </joint>   

  <!-- rf_caster -->
  <link name="rf_caster">
    <visual>
      <geometry>
        <sphere radius="${(wheel_radius+wheel_zoff-(base_height/2))}"/>
      </geometry>
      <material name="Cyan"/>
    </visual>
    <collision>
      <geometry>
        <sphere radius="${(wheel_radius+wheel_zoff-(base_height/2))}"/>
      </geometry>
    </collision>    
  </link>    

  <joint name="rf_caster_joint" type="fixed">
    <parent link="base_link"/>
    <child link="rf_caster"/>
    <origin xyz="0.25 -0.2 ${-(base_height/2)}" rpy="0 0 0"/>
  </joint>   

  <!-- lr_caster -->
  <link name="lr_caster">
    <visual>
      <geometry>
        <sphere radius="${(wheel_radius+wheel_zoff-(base_height/2))}"/>
      </geometry>
      <material name="Cyan">
        <color rgba="0 1.0 1.0 1.0"/>
      </material>
    </visual>  
    <collision>
      <geometry>
        <sphere radius="${(wheel_radius+wheel_zoff-(base_height/2))}"/>
      </geometry>
    </collision>    
  </link>  

  <joint name="lr_caster_joint" type="fixed">
    <parent link="base_link"/>
    <child link="lr_caster"/>
    <origin xyz="-0.25 0.2 ${-(base_height/2)}" rpy="0 0 0"/>
  </joint> 

  <!-- rr_caster -->
  <link name="rr_caster">
    <visual>
      <geometry>
        <sphere radius="${(wheel_radius+wheel_zoff-(base_height/2))}"/>
      </geometry>
      <material name="Cyan">
        <color rgba="0 1.0 1.0 1.0"/>
      </material>
    </visual>  
    <collision>
      <geometry>
        <sphere radius="${(wheel_radius+wheel_zoff-(base_height/2))}"/>
      </geometry>
    </collision>        
  </link>  

  <joint name="rr_caster_joint" type="fixed">
    <parent link="base_link"/>
    <child link="rr_caster"/>
    <origin xyz="-0.25 -0.2 ${-(base_height/2)}" rpy="0 0 0"/>
  </joint>  

<!-- IMU -->
  <link name="bno055">
    <visual>
      <geometry>
        <box size="0.05 0.05 0.05"/>
      </geometry>
    </visual>
    
    <collision>
      <geometry>
        <box size="0.05 0.05 0.05"/>
      </geometry>
    </collision>
      
    <xacro:box_inertia m="0.1" w="0.1" d="0.1" h="0.1"/>
  </link>
    
  <joint name="bno055_joint" type="fixed">
    <parent link="base_link"/>
    <child link="bno055"/>
    <origin xyz="0 0 0.01"/>
  </joint>

<!-- omron -->
  <link name="omron">
    <visual>
      <geometry>
        <box size="0.05 0.07 0.05"/>
      </geometry>
      <material name="Black"/> 
    </visual>
    
    <collision>
      <geometry>
        <box size="0.05 0.07 0.05"/>
      </geometry>
    </collision>
      
    <xacro:box_inertia m="0.1" w="0.1" d="0.1" h="0.1"/>
  </link>
    
  <joint name="omron_joint" type="fixed">
    <parent link="base_link"/>
    <child link="omron"/>
    <origin xyz="0.27 0 ${base_height/2 + 0.025}"/>
  </joint>
</robot>  